Workbook

Sheet Dropdown
A1: Door | B1: Track | C1: Fab Name | D1: Enginering Name | E1: Field Name | G1: yes/no | H1: Installed | I1: Track | J1: Jamb | K1: Lift | L1: Springs | M1: Model | N1: Door Color | O1: Door Stop Color | P1: Door Stop | Q1: Openers | R1: Locks | S1: Lites by | T1: Lites Size | U1: Lites Type | V1: Rollers
C2: " Door / " Track Fabrication | D2: Master | E2: Field | G2: Yes | H2: YES/tear & haul | I2: Jamb Bracket | J2: Wood | K2: 12in std radius | L2: 15M cycles | M2: TF138 | N2: White | O2: White | P2: None | Q2: 2220L Basic Series | R2: None | S2: none | T2: 24" x 12" | U2: 1/8" DSB | V2: 2'' HD SHORT NYLON ROLLER
A3: 1.375 | B3: 2 | C3: 1" 3/8 Door / 2" Track Fabrication | D3: 1 3/8 x 2 Master | E3: 1 3/8 x 2 Field | G3: No | H3: YES/new construction | I3: Angle IN | J3: Wood | K3: 15in std radius | L3: 25M cycles | M3: TR138 | N3: Almond | O3: Almond | P3: PVC | Q3: 6580L Plus Series | R3: Slide Lock | S3: by MFG | T3: 24" x 8" | U3: 1/2" insulated | V3: 2'' HD NYLON LONG STEM ROLLER
A4: 1.375 | B4: 3 | C4: 1" 3/8 Door / 3" Track Fabrication | D4: 1 3/8 x 3 Master | E4: 1 3/8 x 3 Field | H4: NO/customer pick up | I4: Angle OUT | J4: Steel Bolted | K4: LHR front | L4: 50M cycles | M4: AR138 | N4: Sandtone | O4: Sandtone | P4: Clip-on w/ top seal | Q4: 6690L Premium Series | R4: Other (add notes) | S4: by AOD | T4: short panel | U4: frosted ins | V4: 3'' NYLON LONG STEM ROLLER
A5: 2 | B5: 2 | C5: 2" Door / 2" Track Fabrication | D5: 2 x 2 Master | E5: 2 x 2 Field | J5: Masonry | K5: LHR rear | L5: 100M cycles | M5: ARL138 | N5: Brown | O5: Dark Brown | P5: OTHER | Q5: 4690L Premium Heavy Duty Series | T5: long panel | U5: rain ins | V5: 2'' 10 BALL SHORT STEM STEEL ROLLER
A6: 2 | B6: 3 | C6: 2" Door / 3" Track Fabrication | D6: 2 x 3 Master | E6: 2 x 3 Field | J6: Drywall | K6: High Lift | M6: LP138 | N6: Green | O6: Bronze | Q6: 98022 resi jackshaft | T6: Alum full vision | U6: smoke ins | V6: 2'' 10 BALL LONG STEM STEEL ROLLER
A7: 3 | B7: 2 | C7: 3" Door / 2" Track Fabrication | D7: 3 x 2 Master | E7: 3 x 2 Field | K7: Full Vertical | M7: TF II | N7: Earthtone | O7: Black | Q7: 98032 resi jackshaft | V7: 3'' HEAVY DUTY LONG STEM STEEL ROLLER
A8: 3 | B8: 3 | C8: 3" Door / 3" Track Fabrication | D8: 3 x 3 Master | E8: 3 x 3 Field | K8: FRP- Roof pitch | M8: TR II | N8: Beige | O8: Gray | Q8: RJDC7
M9: AR II | N9: Sepia | O9: Green | Q9: JHDC12
M10: ARL II | N10: Black | O10: Woodgrain | Q10: TDC7
M11: LP II | N11: P White | Q11: TDC12
M12: AR25 non | N12: Medium Oak | Q12: Other (please note)
M13: AR25 hits | N13: Golden Oak
M14: RP25 non | N14: Walnut
M15: RP25 hits | N15: Custom
M16: LP25 non
M17: LP25 hits
M18: ARL25 non
M19: ARL25 hits
M20: RS25 non
M21: RS25 hits
M22: RS25 w/steel
M23: RS24 non-smooth
M24: RS24 hits-smooth
M25: RS24 w/stl-smooth
M26: TRX II
M27: ARX II
... M40: Custom

Sheet FAB
A1: {=_xlfn.XLOOKUP(1, (Dropdown!A2:A8=FAB!B15)*(Dropdown!B2:B8=FAB!B16),Dropdown!C2:C8)} -> " Door / " Track Fabrication
A2: Job Information | C2: Notes | D2: Windows
A3: Sold By: | D3: Lites by:
A4: Our Order ID: | D4: Section:
A5: Date Promised: | D5: Panel:
A6: Customer: | D6: Full Vision:
A7: Project: | D7: Lites Size:
A8: Installed: | D8: Lites Type:
A9: Door Location: | D9: Glass Type:
A10: Door Size | D10: Accessories
A11: Side | B11: Feet | C11: Inches
A12: Length
A13: Height
A14: Door Specs | E14: Notes
A15: Door Thickness: | C15: Rollers:
A16: Trck Size: | C16: Center Stile
A17: Des | C17: Model:
A18: Track | C18: Color:
A19: Jamb | C19: Door Stop(Seal):
A20: Lift: | C20: Door Stop Color:
A21: Bottom of Track: | C21: Opener:
A22: Floor to Obstruction: | C22: Locking Device:
A23: Springs: | C23: Windload:
A24: AUTHORIZE TO FABRICATE?
A25: No | C25: DATE AUTHORIZED | D25: =IF(A25="Yes",NOW(),"")
A26: Comments

Sheet Enginering
A1: {=_xlfn.XLOOKUP(1, (Dropdown!A2:A8=FAB!B15)*(Dropdown!B2:B8=FAB!B16),Dropdown!D2:D8)} -> Master | Q1: Height | R1: 2" | S1: 3" | T1: Length 2" Door | U1: Length 3" Door | V1: Clip Style | X1: Height | Z1: Height | AA1: 2" | AB1: 3" | AD1: 22" x 1.5" horizontal angle 14ga short | AF1: Height | AG1: Starter Plate | AH1: Extention | AI1: Junction Plate Each | AJ1: Dub | AL1: Column | AM1: Rollers
A2: Job Info | D2: Door Specs | M2: Width Inches | N2: =(I3*12)+J3 -> 0 | Q2: 6 | R2: 76"x.062 - 2" vertical track | S2: 88"x.102 - 3" vertical track | T2: 5,6,7 | U2: 9,10,11 | X2: =IF(J4="12in std radius", N4+0.2,N4+0.5) -> 0.5 | Z2: 7.5 | AA2: 8'4"x.083 15R - 2" horizontal track | AB2: 9'6"x.102 - 3" horizontal track 15"R | AD2: 82" x 1.5" horizontal angle 14ga short | AF2: 7 | AG2: 23" LHR Starter Angle | AH2: None | AI2: 6 | AJ2: 8'6"x.058 LHR DUB 6"R | AL2: 4 | AM2: 10
A3: Customer: | B3: =IF(ISBLANK(FAB!B6),"",FAB!B6) | D3: Size | E3: =FAB!B12 -> 0 | G3: =FAB!C12 -> 0 | H3: X | I3: =FAB!B13 -> 0 | J3: =FAB!C13 -> 0 | M3: Height Inches | N3: =(E3*12)+G3 -> 0 | Q3: 7 | R3: 76"x.062 - 2" vertical track | S3: 88"x.102 - 3" vertical track | T3: 5,6,7 | U3: 9,10,11 | V3: 105"x2" clip style angle | Z3: 8.5 | AA3: 9'6"x.083 15R - 2" horizontal track | AB3: 9'6"x.102 - 3" horizontal track 15"R | AD3: 137" x 1.5" horizontal angle 13ga long | AF3: 8 | AG3: 23" LHR Starter Angle | AH3: None | AI3: 8 | AJ3: 9'8"x.058 LHR DUB 6"R | AL3: 5 | AM3: 12
A4: Project: | B4: =IF(ISBLANK(FAB!B7),"",FAB!B7) | D4: Des | E4: =IF(ISBLANK(FAB!B17),"",FAB!B17) | G4: Windload | H4: =IF(ISBLANK(FAB!D23),"",FAB!D23) | I4: Lift | J4: =IF(ISBLANK(FAB!B20),"",FAB!B20) | M4: Height Rounded up | N4: =IF(J3>0,I3+1,I3) -> 0 | Q4: 8 | R4: 88"x.062 - 2" vertical track | S4: 88"x.102 - 3" vertical track | T4: 5,6,7, | U4: 9,10,11 | V4: 105"x2" clip style angle | Z4: 9.5 | AA4: 10'6"x.075 15R - 2" horizontal track | AB4: 11'6"x.102 - 3" horizontal track 15"R | AD4: 11'6" x 2" horizontal angle 12ga(138") | AF4: 10 | AG4: 82" LHR Starter Angle | AH4: None | AI4: 3 | AJ4: 11'8"x.062 LHR DUB 6"R | AL4: 6 | AM4: 14
A5: Installed: | B5: =IF(ISBLANK(FAB!B8),"",FAB!B8) | D5: Tracking | E5: =IF(ISBLANK(FAB!B18),"",FAB!B18) | G5: Top of Track | H5: =IF(ISBLANK(FAB!B21),IF(ISBLANK(FAB!B22),"",(FAB!B22-12)),FAB!B21) | I5: LC | J5: =IFERROR(IF(H5>0,H5-N3,0),"") | M5: Height/24 | N5: =PRODUCT(1/24,N3) -> 0 | Q5: 9 | R5: 100"x.062 - 2" vertical track | S5: 112"x.102 - 3" vertical track | T5: 5,6,7,8 | U5: 9,10,11,12 | V5: 129"x2" clip style angle | Z5: 10.5 | AA5: 11'6"x.083 15R - 2" horizontal track | AB5: 11'6"x.102 - 3" horizontal track 15"R | AD5: 13'6" x 2" horizontal angle 12ga(162") | AF5: 12 | AG5: 82" LHR Starter Angle | AH5: 73" LHR Extention Angle | AI5: 0 | AJ5: 13'8"x.075 LHR DUB 6"R | AL5: 7 | AM5: 16
A6: Location: | B6: =IF(ISBLANK(FAB!B9),"",FAB!B9) | D6: Spring | E6: =IF(ISBLANK(FAB!B23),"",FAB!B23) | G6: FtO | H6: =IF(ISBLANK(FAB!B22),IF(ISBLANK(FAB!B21),"",(FAB!B21+12)),FAB!B22) | I6: Chute | J6: =IFERROR(IF(ISBLANK(J5),"",J5-7),"") | Q6: 10 | R6: 112"x.062 - 2" vertical track | S6: 112"x.102 - 3" vertical track | T6: 5,6,7,8 | U6: 9,10,11,12 | V6: 129"x2" clip style angle | Z6: 11.5 | AA6: 13'6"x.083 15R - 2" horizontal track | AB6: 13'6"x.102 - 3" horizontal track 15"R | AD6: 15'6" x 2" horizontal angle 12ga(186") | AF6: 14 | AG6: 82" LHR Starter Angle | AH6: 73" LHR Extention Angle | AI6: 2 | AJ6: 15'8"x.075 LHR DUB 6"R | AL6: 8 | AM6: 18
A7: Promised Date: | B7: =IF(ISBLANK(FAB!B5),"",FAB!B5) | D7: Color | E7: =IF(ISBLANK(FAB!D18),"",FAB!D18) | G7: Jamb | H7: =IF(ISBLANK(FAB!B19),"",FAB!B19) | I7: Windload | J7: =IF(ISBLANK(FAB!D23),"",FAB!D23) | M7: Low Head Room | N7: =IF(OR(J4="LHR front",J4="LHR rear"),"Yes","No") -> No | Q7: 11 | R7: 136"x.075 - 2" vertical track | S7: 136"x.102 - 3" vertical track | T7: 5,6,7,8,9 | U7: 9,10,11,12,14 | V7: 153"x2" clip style angle | Z7: 12.5 | AA7: 13'6"x.083 15R - 2" horizontal track | AB7: 13'6"x.102 - 3" horizontal track 15"R | AL7: 9 | AM7: 20
A8: Job Number: | B8: =IF(ISBLANK(FAB!B4),"",FAB!B4) | D8: Model | E8: =IF(ISBLANK(FAB!D17),"",FAB!D17) | G8: Sections | H8: =IF(INT(N5)=N5,N5,INT(N5)+1) -> 0 | I8: Panels | J8: =INT(IF(E3<8,1,PRODUCT(1/40, N2))) -> 1 | Q8: 12 | R8: 136"x.075 - 2" vertical track | S8: 136"x.102 - 3" vertical track | T8: 5,6,7,8,9 | U8: 9,10,11,12,14 | V8: 153"x2" clip style angle | Z8: 13.5 | AA8: 15'6"x.083 15R - 2" horizontal track | AB8: 15'6"x.102 - 3" horizontal track 15"R | AD8: Shafts | AL8: 10 | AM8: 22
A9: Window Specs | H9: Door Notes | Q9: 13 | R9: 160"x.075 - 2" vertical track | S9: 160"x.102 - 3" vertical track | T9: 5,6,7,8,9,10 | U9: 9,10,11,12,14,16 | V9: 177"x2" clip style angle | Z9: 14.5 | AA9: 15'6"x.083 15R - 2" horizontal track | AB9: 15'6"x.102 - 3" horizontal track 15"R | AD9: 8'9"x1" 16ga tube shaft | AF9: Spring Gauge | AG9: Diameter | AH9: Comercial | AI9: Residential | AJ9: Type
A10: Lites | B10: =IF(ISBLANK(FAB!E3),"",FAB!E3) | D10: Section | E10: =IF(ISBLANK(FAB!E4),"",FAB!E4) | G10: Glass Type: | H10: =IF(ISBLANK(FAB!E15),"",FAB!E15) | Q10: 14 | R10: 160"x.075 - 2" vertical track | S10: 160"x.102 - 3" vertical track | T10: 5,6,7,8,9,10 | U10: 9,10,11,12,14,16 | V10: 177"x2" clip style angle | Z10: 15.5 | AB10: 17'6"x.102 - 3" horizontal track 15"R | AD10: 9'9"x1" 16ga tube shaft | AF10: 0.207 | AG10: 2" | AH10: S207X2 | AI10: Aluminum Spring LW 250 x 2 x 34 1/2" | AJ10: LW
A11: Lite Size | B11: =IF(ISBLANK(FAB!E7),"",FAB!E7) | D11: Panel | E11: =IF(ISBLANK(FAB!E5),"",FAB!E5) | G11: =IF(ISBLANK(FAB!E9),"",FAB!E9) | Q11: 15 | R11: 184"x.075 - 2" vertical track | S11: 184"x.102 - 3" vertical track | V11: 201"x2" clip style angle | Z11: 16.5 | AB11: 17'6"x.102 - 3" horizontal track 15"R | AD11: 10'9"x1" 14ga tube shaft | AF11: 0.218 | AG11: 2 5/8" | AH11: S207X2X40LW | AI11: Aluminum Spring RW 250 x 2 x 34 1/2" | AJ11: 1 Pair
A12: Lite Type | B12: =IF(ISBLANK(FAB!E8),"",FAB!E8) | D12: Full Vision | E12: =IF(ISBLANK(FAB!E6),"",FAB!E6) | Q12: 16 | R12: 184"x.075 - 2" vertical track | S12: 184"x.102 - 3" vertical track | V12: 201"x2" clip style angle | Z12: 17.5 | AD12: 16'9"x1" 16ga tube shaft | AF12: 0.225 | AG12: 3 3/4" | AH12: S207X2X40RW | AI12: BLACK SPRING LW 273 X 2 X 41" | AJ12: 2 Pair
A13: Job Notes | D13: Accessories | G13: Authorized to Fabricate? | M13: no 11 or 13 | Q13: 17 | Z13: 18.5 | AD13: 18'9"x1" 14ga tube shaft | AF13: 0.234 | AG13: 6" | AH13: S218X2 | AI13: BLACK SPRING RW 273 X 2 X 41" | AJ13: 1 Pair Duplex
A14: =IF(ISBLANK(FAB!C3),"",FAB!C3) | D14: =IF(ISBLANK(FAB!D11),"",FAB!D11) | G14: =FAB!A25 -> No | H14: =IF(ISBLANK(FAB!D25),"",FAB!D25) | M14: no 9 in lhr | Q14: 18 | Z14: 7.2 | AA14: 8'6"x.062 12R - 2" horizontal track | AB14: 8'6"x.062 12R - 2" horizontal track | AD14: solid shaft galvanized | AF14: 0.243 | AH14: S218X2X40LW | AI14: BLUE SPRING LW 234 X 2 X 27 1/2" | AJ14: 2 Pair Duplex
G15: Hinges | Z15: 8.2 | AA15: 9'6"x.062 12R - 2" horizontal track | AB15: 9'6"x.062 12R - 2" horizontal track | AF15: 0.25 | AH15: S218X2X40RW | AI15: BLUE SPRING RW 234 X 2 X 27 1/2"
G16: Additional | H16: Type | I16: Hinges | J16: Bolts Needed | M16: 80 | O16: 1/8" | Q16: Sections | R16: 1 | S16: 2 | T16: 3 | U16: 4 | V16: 5 | W16: 6 | Z16: 9.2 | AA16: 10'6"x.083 12R - 2" horizontal track | AB16: 10'6"x.083 12R - 2" horizontal track | AF16: 0.262 | AH16: S225X2 | AI16: BROWN SPRING LW 243 X 2 X 29"
A17: Track | H17: #1 hinge 14ga | I17: =IFERROR(T26,0) -> 0 | J17: =IFERROR((I17+G17)*4,0) -> 0 | M17: 81 | O17: 5/32" | Q17: 4 | R17: 3 | S17: 3 | T17: 6 | U17: 9 | V17: 12 | W17: 15 | Z17: 10.2 | AA17: 11'6"x.083 12R - 2" horizontal track | AB17: 11'6"x.083 12R - 2" horizontal track | AF17: 0.273 | AH17: S225X2X40LW | AI17: BROWN SPRING RW 243 X 2 X 29"
A18: Vertical | B18: =IFERROR(IF(FAB!B16=2,VLOOKUP(N4,Table3[],2),VLOOKUP(N4,Table3[],3)),"") | D18: Low Head Room | H18: #2 hinge 14ga | I18: =T27 -> 0 | J18: =(I18+G18)*4 -> 0 | M18: 82 | O18: 3/16" | Q18: 5 | R18: 4 | S18: 4 | T18: 7 | U18: 10 | V18: 13 | W18: 16 | Z18: 11.2 | AA18: 13'6"x.083 12R - 2" horizontal track | AB18: 13'6"x.083 12R - 2" horizontal track | AF18: 0.283 | AH18: S225X2X40RW | AI18: GOLD SPRING LW 243 X 2 X 34 1/2"
A19: =IF(E5="Jamb Bracket","Jamb Bracket 2 EA","Angle Mount 2 EA") -> Angle Mount 2 EA | B19: =IFERROR(IF(FAB!B15=2,IF(E5="Jamb Bracket",VLOOKUP(N4,Table3[],4),VLOOKUP(N4,Table3[],6)),IF(E5="Jamb Bracket",VLOOKUP(N4,Table3[],5),VLOOKUP(N4,Table3[],6))),"") | D19: Starter Plate | E19: =IF($N$7="Yes",VLOOKUP($N$4,Table6[],2)) -> FALSE | F19: =IF(E19>" ","2"," ") -> 2 | H19: #3 hinge 14ga | I19: =T28 -> 0 | J19: =(I19+G19)*4 -> 0 | M19: 83 | Q19: 6 | R19: 5 | S19: 5 | T19: 8 | U19: 11 | V19: 14 | W19: 17 | Z19: 12.2 | AA19: 13'6"x.083 12R - 2" horizontal track | AB19: 13'6"x.083 12R - 2" horizontal track | AF19: 0.295 | AH19: S234X2 | AI19: GOLD SPRING RW 243 X 2 X 34 1/2"
A20: Off Set Clips / Splice | B20: =IFERROR(IF(FAB!B15=2,VLOOKUP(N4,Table3[],4),VLOOKUP(N4,Table3[],5)),"") | D20: Extension | E20: =IF($N$7="Yes",VLOOKUP($N$4,Table6[],3)) -> FALSE | F20: =IF(E20>" ","1"," ") -> 1 | H20: #4 hinge 14ga | I20: =T29 -> 0 | J20: =(I20+G20)*4 -> 0 | M20: 84 | Q20: 7 | R20: 6 | S20: 6 | T20: 9 | U20: 12 | V20: 15 | W20: 18 | Z20: 13.2 | AA20: 15'6"x.083 12R - 2" horizontal track | AB20: 15'6"x.083 12R - 2" horizontal track | AF20: 0.306 | AH20: S234X2X40LW | AI20: GREEN SPRING LW 262 X 2 X 34"
A21: Horizontal | D21: Junction Plate | E21: =IF($N$7="Yes",VLOOKUP($N$4,Table6[],4)) -> FALSE | F21: =E21 -> FALSE | H21: #5 hinge 14ga | I21: =T30 -> 0 | J21: =(I21+G21)*4 -> 0 | M21: 85 | Q21: 8 | R21: 7 | S21: 7 | T21: 10 | U21: 13 | V21: 16 | W21: 19 | Z21: 14.2 | AA21: 15'6"x.083 12R - 2" horizontal track | AB21: 15'6"x.083 12R - 2" horizontal track | AF21: 0.312 | AH21: S234X2X40RW | AI21: GREEN SPRING RW 262 X 2 X 34"
A22: Horizontal Angle | B22: 22" x 1.5" horizontal angle 14ga short | D22: DUB | E22: =IF($N$7="Yes",VLOOKUP($N$4,Table6[],5)) -> FALSE | F22: =IF(E22>" ","1"," ") -> 1 | H22: #6 hinge 13ga | I22: =T31 -> 0 | J22: =(I22+G22)*4 -> 0 | M22: 86 | Q22: 9 | R22: 8 | S22: 8 | T22: 11 | U22: 14 | V22: 17 | W22: 20 | AF22: 0.319 | AH22: S243X2 | AI22: LITE BLUE SPRING LW 283 X 2 X 44"
A23: Springs | E23: Weight | H23: #7 hinge 11ga | I23: =T32 -> 0 | J23: =(I23+G23)*4 -> 0 | M23: 87 | Q23: 10 | R23: 9 | S23: 9 | T23: 12 | U23: 15 | V23: 18 | W23: 21 | AF23: 0.331 | AH23: S243X2X45LW | AI23: LITE BLUE SPRING RW 283 X 2 X 44"
A24: Type | B24: Spring 1 | D24: Spring 2 | E24: Section | H24: #8 hinge 11ga | I24: =T33 -> 0 | J24: =(I24+G24)*4 -> 0 | M24: 88 | AF24: 0.343 | AH24: S243X2X45RW | AI24: ORANGE SPRINGLW 218 X 2 X 23 1/4"
A25: Wire Gauge | E25: Hardwear | H25: #9 hinge 11ga | I25: =T34 -> 0 | J25: =(I25+G25)*4 -> 0 | M25: 89 | Q25: Column1 | R25: DES | S25: Even | T25: Total | V25: #1 Hinges | AF25: 0.362 | AH25: S250X2 | AI25: ORANGE SPRINGRW 218 X 2 X 23 1/4"
A26: Diameter | E26: Struts | G26: =SUM(G17:G25) -> 0 | H26: Total | I26: =SUM(I17:I25) -> 0 | J26: =SUM(J17:J25) -> 0 | M26: 90 | Q26: # 1 Hinges | R26: =IF(AND($E$4="Yes",$H$8>=2),2,0) -> 0 | S26: =IF($H$8>=2,2,0) -> 0 | T26: =SUM(Table1[[#This Row],[DES]]+Table1[[#This Row],[Even]]+V26) -> #N/A | V26: {=INDEX(R17:W23,MATCH(H8,Q17:Q23),J8)} -> #N/A | AF26: 0.375 | AH26: S250X2X50LW | AI26: PINK SPRING LW 234 X 2 X 30"
A27: Length In | E27: Total | F27: =SUM(F24:F26) -> 0 | G27: Parts | M27: 91 | Q27: # 2 Hinges | R27: =IF(AND($E$4="Yes",$H$8>=3),2,0) -> 0 | S27: =IF($H$8>=3,2,0) -> 0 | T27: =Table1[[#This Row],[DES]]+Table1[[#This Row],[Even]] -> 0 | AF27: 0.393 | AH27: S250X2X50RW | AI27: PINK SPRING RW 234 X 2 X 30"
A28: Turns | E28: Struts | G28: =I3-4 -> -4 | H28: Pull Rope | J28: #1 Steel Bag | M28: 92 | Q28: # 3 Hinges | R28: =IF(AND($E$4="Yes",$H$8>=4),2,0) -> 0 | S28: =IF($H$8>=4,2,0) -> 0 | T28: =Table1[[#This Row],[DES]]+Table1[[#This Row],[Even]] -> 0 | AF28: 0.406 | AH28: S262X2 | AI28: PURPLE SPRING LW 225 X 2 X 28
A29: Residential | F29: Strut 1 | G29: =I3 -> 0 | H29: Dry Wall Screws | J29: #2 Steel Bag | M29: 93 | Q29: # 4 Hinges | R29: =IF(AND($E$4="Yes",$H$8>=5),2,0) -> 0 | S29: =IF($H$8>=5,2,0) -> 0 | T29: =Table1[[#This Row],[DES]]+Table1[[#This Row],[Even]] -> 0 | AH29: S262X2X56LW | AI29: PURPLE SPRINGRW 225 X 2 X 28
A30: Comercial | G30: 1 | H30: 5 hole Step Plate | J30: #4 Comm Pkg | M30: 94 | Q30: # 5 Hinges | R30: =IF(AND($E$4="Yes",$H$8>=6),2,0) -> 0 | S30: =IF($H$8>=6,2,0) -> 0 | T30: =Table1[[#This Row],[DES]]+Table1[[#This Row],[Even]] -> 0 | AH30: S262X2X56RW | AI30: RED SPRINGLW 262 X 2 X 38"
A31: Special Order | F31: QTY | G31: 1 | H31: closed grip lift handle | I31: Yes | J31: Door Sticker | M31: 95 | Q31: # 6 Hinges | R31: =IF(AND($E$4="Yes",$H$8>=7),2,0) -> 0 | S31: =IF($H$8>=7,2,0) -> 0 | T31: =Table1[[#This Row],[DES]]+Table1[[#This Row],[Even]] -> 0 | AH31: S273X2 | AI31: RED SPRING RW 262 X 2 X 38"
A32: Type | F32: Strut 2 | G32: 1 | H32: unilock commercial | J32: 2nd Cab | M32: 96 | Q32: # 7 Hinges | R32: =IF(AND($E$4="Yes",$H$8>=8),2,0) -> 0 | S32: =IF($H$8>=8,2,0) -> 0 | T32: =Table1[[#This Row],[DES]]+Table1[[#This Row],[Even]] -> 0 | AH32: S273X2X50LW | AI32: WHITE SPRING LW 207 X 2 X 21 1/2"
A33: Shaft | G33: =J26+((E31+E34)*10) -> 0 | H33: Bolt Bag Required | I33: 1 | J33: #1 Bolt Bag | M33: 97 | Q33: # 8 Hinges | R33: =IF(AND($E$4="Yes",$H$8>=9),2,0) -> 0 | S33: =IF($H$8>=9,2,0) -> 0 | T33: =Table1[[#This Row],[DES]]+Table1[[#This Row],[Even]] -> 0 | AH33: S273X2X50RW | AI33: WHITE SPRING RW 207 X 2 X 21 1/2"
A34: 10'9"x1" 14ga tube shaft | C34: Cut To | D34: 5 | F34: QTY | G34: leaf bumper spring w/ bracket | H34: Spring Bummbers | I34: coupling | J34: Coupler | M34: 98 | Q34: # 9 Hinges | R34: =IF(AND($E$4="Yes",$H$8>=10),2,0) -> 0 | S34: =IF($H$8>=10,2,0) -> 0 | T34: =Table1[[#This Row],[DES]]+Table1[[#This Row],[Even]] -> 0 | AH34: S283X2
A35: 10'9"x1" 14ga tube shaft | C35: Cut To | D35: 10 | F35: Cut To | M35: 99 | AH35: S283X2X56LW
A36: Drum | C36: End Bearing Plates | M36: 100 | AH36: S283X2X56RW
A37: Flag | C37: Splice | G37: 1/4" x 3" keyway bent | J37: Key | M37: 101 | Q37: Drums | R37: Code | S37: End Plate | T37: Code | U37: Flag | V37: Code | W37: Splice | X37: Code | Y37: Bottom Fixture | Z37: Code2 | AA37: Top Fixture | AB37: Code 3 | AC37: CAB | AD37: Code 4 | AH37: S295X2
A38: Cables, Bearings and Fixtures | G38: Comments | M38: 102 | Q38: 4x8 SR drum | R38: HDRU408 | S38: EBF 3 3/8" residential 12ga. w/brg | T38: HWEBP01 | U38: Resi slotted flag angle PAIR | V38: HWFB001 | W38: #6 splice plate high lift | X38: HWLP006 | Y38: BB-100 | Z38: HWBF001 | AA38: commercial adjustable top bracket | AB38: HWTF002 | AC38: SAN 3 3/8" resi 12ga no brg notched | AD38: HWCBP01 | AH38: S295X2X56LW
B39: Inches | D39: Diameter | F39: CAB | G39: =IF(ISBLANK(FAB!A27),"",FAB!A27) | M39: 103 | Q39: 400-12 SR drum | R39: HDRU412 | S39: #7-3 3/8" wood EBF 11ga w/brg | T39: HWEBP07 | U39: 19" vertical angle 13ga x2 | V39: HWVA001 | W39: #8 splice plate high lift | X39: HWLP008 | Y39: BB-90 | Z39: HWBFL90 | AA39: residential adjustable top bracket | AB39: HWTF001 | AC39: SAN 3 3/8" comm 11ga no brg notched | AD39: HWCBP02 | AH39: S295X2X56RW
A40: =IF(E4="Yes",_xlfn.XLOOKUP(H8,Table14[Column],Table14[Rollers]),"4") -> 4 | B40: Long Rollers | C40: =IFERROR(IF(E4="Yes","0",_xlfn.XLOOKUP(H8,Table14[Column],Table14[Rollers])-4),"") | D40: Short Rollers | F40: QTY | M40: 104 | Q40: 5-18 SR drum(5250-18) | R40: HDRU518 | S40: #7-3 3/8" steel EBF 11ga w/brg | T40: HWEBP07 | W40: #10 splice plate high lift | X40: HWLP010 | Y40: BB-4 1 5/8" SF | Z40: HWBF004 | AA40: 2" low headroom top bracket | AB40: HWTFL01 | AC40: SAN 4 3/8" comm 8ga no brg notched | AD40: HWCBP03 | AH40: S243X258
...

Sheet Field
A1: {=_xlfn.XLOOKUP(1, (Dropdown!A2:A8=FAB!B15)*(Dropdown!B2:B8=FAB!B16),Dropdown!E2:E8)} -> Field
A2: Job Info | C2: Door Specs
A3: Customer: | B3: =IF(ISBLANK(FAB!B6),"",FAB!B6) | C3: Size | D3: =FAB!B13 -> 0 | E3: =FAB!C13 -> 0 | F3: X | G3: =FAB!B12 -> 0 | H3: =FAB!C12 -> 0
A4: Project: | B4: =IF(ISBLANK(FAB!B7),"",FAB!B7) | C4: Des | D4: =IF(ISBLANK(FAB!B17),"",FAB!B17) | E4: Windload | F4: =IF(ISBLANK(FAB!D23),"",FAB!D23) | G4: Lift | H4: =IF(ISBLANK(FAB!B20),"",FAB!B20)
A5: Installed: | B5: =IF(ISBLANK(FAB!B8),"",FAB!B8) | C5: Tracking | D5: =IF(ISBLANK(FAB!B18),"",FAB!B18) | E5: Top of Track | F5: =IF(ISBLANK(FAB!B21),IF(ISBLANK(FAB!B22),"",(FAB!B22-12)),FAB!B21) | G5: LC | H5: =IF(F5>0,F5-L3,0) -> #VALUE!
A6: Location: | B6: =IF(ISBLANK(FAB!B9),"",FAB!B9) | C6: Spring | D6: =IF(ISBLANK(FAB!B23),"",FAB!B23) | E6: Floor to obstuction | F6: =IF(ISBLANK(FAB!B22),IF(ISBLANK(FAB!B21),"",(FAB!B21+12)),FAB!B22) | G6: Chute | H6: =IF(ISBLANK(H5),"",H5-7) -> #VALUE!
A7: Promised Date: | B7: =FAB!B5 -> 0 | C7: Color | D7: =FAB!D18 -> 0 | E7: Jamb | F7: =IF(ISBLANK(FAB!B19),"",FAB!B19) | G7: Windload | H7: =IF(ISBLANK(FAB!D23),"",FAB!D23)
A8: Job Number: | B8: =FAB!B4 -> 0 | C8: Model | D8: =FAB!D17 -> 0 | E8: Sections | F8: =IF(INT(L5)=L5,L5,INT(L5)+1) -> 0 | G8: Panels | H8: =INT(IF(D3<8,1,PRODUCT(1/40, L2))) -> 1
A9: Track Assembly | C9: Windows
A10: Horizontal Track | B10: =Enginering!E18 -> 0 | C10: Lites: | D10: =FAB!E3 -> 0 | E10: Size/Style: | F10: =Enginering!B11 | G10: Type | H10: =FAB!E8 -> 0
A11: Horizontal Angle | B11: =Enginering!B22 -> 22" x 1.5" horizontal angle 14ga short | C11: Hardwear Box
A12: Vertical Track | B12: =Enginering!B18 | C12: CAB, spring anchor plate | E12: =Enginering!E40 -> 0 | F12: =Enginering!B36 -> 0 | H12: Pair
A13: =IF(D5="Jamb Bracket","Jamb Bracket Pair","Angle Mount Pair") -> Angle Mount Pair | B13: =Enginering!B19 | C13: 1" Bearing | E13: =E12 -> 0 | F13: =Enginering!D36 -> 0 | H13: Pair
A14: Track Clips 2 EA | B14: =Enginering!B20 | C14: 1" nylon bearing for LHR spacer | E14: =Enginering!R52 -> 0 | F14: Bottom Fixture | G14: =Enginering!A41 -> BB-100 | H14: Pair
A15: 1 pair | B15: =Enginering!E19 -> FALSE | C15: Cable Inches | E15: =Enginering!A39 -> 0 | F15: Top Fixture | G15: =Enginering!C41 -> commercial adjustable top bracket
A16: =Enginering!F20 -> 1 | B16: =Enginering!E20 -> FALSE | C16: Cable Dia | E16: =Enginering!C39 -> 0 | F16: Top Ammount | G16: =Enginering!C42 -> 2
A17: =Enginering!F21 -> FALSE | B17: =Enginering!D21 -> Junction Plate | C17: =Enginering!H17 -> #1 hinge 14ga | E17: =Enginering!G17+Enginering!I17 -> 0 | F17: Shaft
A18: =Enginering!F22 -> 1 | B18: =Enginering!E22 -> FALSE | C18: =Enginering!H18 -> #2 hinge 14ga | E18: =Enginering!G18+Enginering!I18 -> 0 | F18: Shaft | H18: Cut To
A19: HL splice | B19: =Enginering!D37 -> 0 | C19: =Enginering!H19 -> #3 hinge 14ga | E19: =Enginering!G19+Enginering!I19 -> 0 | F19: =Enginering!A34 -> 10'9"x1" 14ga tube shaft | H19: =Enginering!D34 -> 5
A20: Flag | B20: =Enginering!B37 -> 0 | C20: =Enginering!H20 -> #4 hinge 14ga | E20: =Enginering!G20+Enginering!I20 -> 0 | F20: =Enginering!A35 -> 10'9"x1" 14ga tube shaft | H20: =Enginering!D35 -> 10
A21: Splice | B21: =Enginering!D37 -> 0 | C21: =Enginering!H21 -> #5 hinge 14ga | E21: =Enginering!G21+Enginering!I21 -> 0 | F21: =Enginering!J34 -> Coupler | H21: =IF(F21>" ",1," ") -> 1
A22: Fastners | C22: =Enginering!H22 -> #6 hinge 13ga | E22: =Enginering!G22+Enginering!I22 -> 0 | F22: =Enginering!G37 -> 1/4" x 3" keyway bent | H22: =IF(F22>" ",4," ") -> 4
A23: =Enginering!G29 -> 0 | B23: =Enginering!H29 -> Dry Wall Screws | C23: =Enginering!H23 -> #7 hinge 11ga | E23: =Enginering!G23+Enginering!I23 -> 0 | F23: DES | H23: =Enginering!E4
A24: =Enginering!I33 -> 1 | B24: =Enginering!J33 -> #1 Bolt Bag | C24: =Enginering!H24 -> #8 hinge 11ga | E24: =Enginering!G24+Enginering!I24 -> 0 | F24: =Enginering!B40 -> Long Rollers | H24: =Enginering!A40 -> 4
A25: =Enginering!I28 -> 0 | B25: =Enginering!J28 -> #1 Steel Bag | C25: =Enginering!H25 -> #9 hinge 11ga | E25: =Enginering!G25+Enginering!I25 -> 0 | F25: =Enginering!D40 -> Short Rollers | H25: =Enginering!C40
A26: =Enginering!I29 -> 0 | B26: =Enginering!J29 -> #2 Steel Bag | C26: Rope Feet | E26: =Enginering!G28 -> -4 | F26: Step Plate | H26: =Enginering!G30 -> 1
A27: =Enginering!I30 -> 0 | B27: =Enginering!J30 -> #4 Comm Pkg | C27: Handle | E27: =Enginering!G31 -> 1 | F27: Lock | H27: =Enginering!G32 -> 1
A28: =Enginering!I32 -> 0 | B28: =Enginering!J32 -> 2nd Cab | C28: =Enginering!G34 -> leaf bumper spring w/ bracket | E28: =IF(C28="leaf bumper spring w/ bracket","1"," ") -> 1 | F28: Flag | G28: =IF(H4="High Lift"," ",B20) -> 0
C29: Splice | D29: =IF(H4="High Lift"," ",B21) -> 0
A30: Struts | C30: Springs
A31: =Enginering!E31 -> 0 | B31: =Enginering!E29 -> 0 | C31: =Enginering!F24 -> 0 | D31: Section Weight | E31: =Enginering!B32 -> 0 | F31: Spring 1 | H31: Spring 2
A32: =Enginering!E34 -> 0 | B32: =Enginering!E32 -> 0 | C32: =Enginering!F25 -> 0 | D32: Hardwear Weight | E32: Wire Gauge | F32: =Enginering!B25 -> 0 | H32: =Enginering!D25 -> 0
A33: =Enginering!E35 -> 0 | B33: Cut To | C33: =Enginering!F26 -> 0 | D33: Strut Weight | E33: Diameter | F33: =Enginering!B26 -> 0 | H33: =Enginering!D26 -> 0
A34: Notes | C34: =Enginering!F27 -> 0 | D34: Total | E34: Length In | F34: =Enginering!B27 -> 0 | H34: =Enginering!D27 -> 0
A35: =IF(ISBLANK(FAB!A27),"",FAB!A27) | E35: Turns | F35: =Enginering!B28 -> 0 | H35: =Enginering!D28 -> 0
E36: Residential | F36: =Enginering!B29 -> 0 | H36: =Enginering!D29 -> 0
E37: Comercial | F37: =Enginering!B30 -> 0 | H37: =Enginering!D30 -> 0
E38: Special Order | F38: =Enginering!B31 -> 0 | H38: =Enginering!D31 -> 0
